Workbook

Sheet README
A1: FEATURE VALUE SCORING FRAMEWORK
A2: Purpose: a shared scoring surface completed by humans and/or a market research agent, then consumed by feature prioritization agents. Also tracks customer-reported defects and internally-found bugs (Item Type = Defect) alongside new-feature ideas, so both compete in one ranked backlog.
A4: HOW TO USE
A5: 1. Add one row per feature idea on the Scoring sheet. Feature ID and Name are required; link the feature brief in the Brief Reference column.
A6: 2. For Feature rows: score the eight input dimensions (columns G-N) on a 1-10 scale using the anchors on the Rubric sheet. For Defect rows: set Item Type (V), Defect Source (W), and Severity (X) instead - see the DEFECTS & BUGS section below.
A7: 3. Record evidence sources and rationale (columns O-P). Agents must cite sources; humans should note the basis for judgment calls.
A8: 4. Columns Q-U calculate automatically. Do not type into them.
A9: 5. Adjust dimension weights on the Config sheet to match product strategy. Weights must sum to 100% (checked in Config!B9).
A11: SCORING MODEL
A12: Weighted Value = SUM(dimension score x weight) across Reach, User Value, Business Value, Strategic Alignment, Time Sensitivity.
A13: Priority Score (0-100) = MIN(100, Weighted Value x Confidence Multiplier x Risk Factor / Effort x 20). The cap only binds for very low effort (1 = hours-to-a-day on the 10-pt scale).
A14: Confidence and Risk map to multipliers via lookup tables on the Config sheet, so a low-confidence or high-risk idea is discounted rather than excluded.
... A27: 6. Once a Defect row is Scored or Prioritized, run /fix-defect-or-bug <feature_id> to dispatch the fix pipeline (reproduce, fail a regression test, fix, verify, review).

Sheet Config
A1: CONFIGURATION - dimension weights and multiplier maps
A3: Value Dimension Weights (must sum to 100%)
A4: Reach | B4: 0.2
A5: User Value | B5: 0.25
A6: Business Value | B6: 0.25
A7: Strategic Alignment | B7: 0.2
A8: Time Sensitivity | B8: 0.1
A9: Weight check | B9: =IF(SUM(B4:B8)=1,"OK","ERROR: weights must sum to 100%") -> OK
A11: Confidence Multiplier Map | D11: Risk Factor Map | G11: Defect Severity -> Priority Base Map | I11: Defect Reach -> Multiplier Map
A12: 1 | B12: 0.45 | D12: 1 | E12: 1 | G12: 1 | H12: 10 | I12: 1 | J12: 0.75
A13: 2 | B13: 0.5 | D13: 2 | E13: 1 | G13: 2 | H13: 30 | I13: 2 | J13: 0.8
A14: 3 | B14: 0.58 | D14: 3 | E14: 0.95 | G14: 3 | H14: 55 | I14: 3 | J14: 0.85
A15: 4 | B15: 0.65 | D15: 4 | E15: 0.9 | G15: 4 | H15: 80 | I15: 4 | J15: 0.9
A16: 5 | B16: 0.73 | D16: 5 | E16: 0.85 | G16: 5 | H16: 100 | I16: 5 | J16: 0.95
A17: 6 | B17: 0.8 | D17: 6 | E17: 0.8 | I17: 6 | J17: 1
A18: 7 | B18: 0.85 | D18: 7 | E18: 0.75 | I18: 7 | J18: 1.05
A19: 8 | B19: 0.9 | D19: 8 | E19: 0.7 | I19: 8 | J19: 1.1
A20: 9 | B20: 0.95 | D20: 9 | E20: 0.65 | I20: 9 | J20: 1.15
A21: 10 | B21: 1 | D21: 10 | E21: 0.6 | I21: 10 | J21: 1.2
A23: Confidence score (1-10) -> multiplier applied to Weighted Value (RICE-style discount for weak evidence). Even keys carry the pre-2026-07 5-pt map values (old score x2 = same multiplier).
A24: Risk score (1-10) -> factor applied to Weighted Value (higher risk = larger discount). Even keys carry the pre-2026-07 5-pt map values.
A26: Defect severity (still 1-5; industry Sev alignment) -> base priority-score map (severity fast-track model; bypasses weighted_value, strategic_alignment, and effort entirely).
A27: Defect reach (1-10) -> small multiplier (customer breadth is secondary to severity in the fast-track model, unlike the Feature formula where it's a primary weighted dimension).
A28: defect_priority_score = MIN(100, ROUND(severity_base x reach_factor x confidence_mult, 1)). confidence_mult is the same lookup used by the Feature formula (Confidence Multiplier Map above).

Sheet Rubric
A1: SCORING RUBRIC - anchors for each 1-10 dimension (even scores = the pre-2026-07 5-pt anchors; Severity stays 1-5)
B2: 1 | C2: 2 | D2: 3 | E2: 4 | F2: 5 | G2: 6 | H2: 7 | I2: 8 | J2: 9 | K2: 10
A3: Dimension | B3: 1 | C3: 2 | D3: 3 | E3: 4 | F3: 5
A4: Reach | B4: Touches <3% of target users; rare edge case | C4: Touches <5% of target users or a rare edge case | D4: Touches 5-10% of users, infrequent use | E4: Touches 5-15% of users, or infrequent use | F4: Touches 15-25% of users with regular use | G4: Touches 15-40% of users with regular use | H4: Touches 40-55% of users frequently | I4: Touches 40-70% of users frequently | J4: Touches 70-85% of users in daily workflows | K4: Touches >70% of users in core daily workflows
A5: User Value | B5: Purely cosmetic; no user would notice its absence | C5: Cosmetic; no measurable pain relieved | D5: Minor convenience; trivial workaround | E5: Minor convenience; mild pain, easy workaround exists | F5: Real pain, but the workaround is tolerable | G5: Solves a real pain with a clumsy workaround today | H5: Frequent pain; workaround is costly or error-prone | I5: Removes a frequent, significant pain point | J5: Near top-tier pain, or partially unlocks a new job-to-be-done | K5: Eliminates a top-3 user pain or unlocks a new job-to-be-done
A6: Business Value | B6: No conceivable business effect | C6: No plausible revenue/retention/cost effect | D6: Marginal, hard-to-attribute effect | E6: Indirect or small effect on a business metric | F6: Measurable effect on a secondary metric | G6: Measurable effect on conversion, retention, or cost | H6: Clear contributor to a core business metric | I6: Clear driver of revenue, expansion, or churn reduction | J6: Materially shifts a top-line metric or defends key revenue | K6: Opens a new segment/market or defends a major revenue stream
A7: Strategic Alignment | B7: Actively works against the product strategy | C7: Contradicts stated product strategy | D7: Orthogonal to strategy; slight tension | E7: Unrelated to strategy; opportunistic | F7: Tangentially related to a strategic theme | G7: Loosely supports a strategic theme | H7: Clearly supports a strategic theme | I7: Directly advances a current strategic pillar | J7: Key enabler of a strategic pillar | K7: Critical-path item for the product vision
A8: Time Sensitivity | B8: No pressure; waiting costs nothing or value grows | C8: No time pressure; value stable indefinitely | D8: Value decays very slowly (multi-year horizon) | E8: Value decays slowly over years | F8: Advantage to shipping within ~18 months | G8: Meaningful advantage to shipping this year | H8: Competitive/market window within 3 quarters | I8: Competitive/market window within 2 quarters | J8: Window within 1 quarter | K8: Hard deadline (regulation, contract, event) or closing window
A9: Confidence | B9: Guesswork; assumptions untested, no evidence sought | C9: Pure speculation; no supporting evidence | D9: A single anecdote | E9: Anecdotes or a single data point | F9: Multiple converging anecdotes; thin data | G9: Directional data: some interviews, analogous benchmarks | H9: Good data with known gaps | I9: Solid data: surveys, usage analytics, competitor evidence | J9: Strong multi-source data; small residual unknowns | K9: Validated: experiments, pilots, or committed customer demand
A10: Effort | B10: Hours to a day; trivial change | C10: Days; single dev, no design or new infra | D10: About a week; single dev | E10: 1-2 weeks; small change, minimal coordination | F10: 2-3 weeks; light cross-discipline coordination | G10: 3-6 weeks; multi-discipline, some unknowns | H10: 6-10 weeks; significant unknowns | I10: 1-2 quarters; significant architecture or integration work | J10: 2-3 quarters; major cross-team program | K10: >3 quarters; major platform work or new subsystem
A11: Risk | B11: Fully understood; trivially reversible | C11: Well-understood; easily reversible | D11: Small unknowns; cheap to reverse | E11: Minor unknowns; reversible with modest cost | F11: Moderate unknowns or a soft third-party dependency | G11: Some technical/market unknowns or third-party dependency | H11: Multiple unknowns; reversal is painful | I11: Hard-to-reverse decision or fragile dependencies | J11: Effectively one-way without major cost | K11: One-way door: public API, data model, pricing, or compliance exposure
A12: Severity (Defect rows only) | B12: Cosmetic; no functional impact, no workaround needed | C12: Minor; workaround exists, low friction (industry Sev4) | D12: Moderate; feature degraded or blocked with a workaround (industry Sev3) | E12: Major; feature unusable, no reasonable workaround, no data loss (industry Sev2) | F12: Critical; data loss, security exposure, or outage blocking core workflows (industry Sev1) | G12: Severity stays on a 1-5 scale (industry Sev4...Sev1 alignment); columns 6-10 do not apply.

Sheet Scoring
A1: FEATURE VALUE SCORING
A2: Blue columns = inputs (human or research agent). Grey columns = calculated; do not edit. Anchors: see Rubric sheet. Item Type (V) selects the scoring path: Feature uses the weighted-value formula (Q-U); Defect uses the severity fast-track formula (see Config sheet), leaving Weighted Value (Q) blank.
A3: Feature ID | B3: Feature Name | C3: Brief Reference | D3: Status | E3: Scored By | F3: Date Scored | G3: Reach (1-10) | H3: User Value (1-10) | I3: Business Value (1-10) | J3: Strategic Alignment (1-10) | K3: Time Sensitivity (1-10) | L3: Confidence (1-10) | M3: Effort (1-10) | N3: Risk (1-10) | O3: Evidence & Sources | P3: Rationale Notes | Q3: Weighted Value | R3: Confidence Mult | S3: Risk Factor | T3: Priority Score (0-100) | U3: Rank | V3: Item Type | W3: Defect Source | X3: Severity (1-5)
A4: F-001 | B4: Adhere to a Design System | C4: briefs/F-001-adhere-to-design-system.md | D4: Prioritized | E4: Market Research Agent | F4: 46210 | G4: 10 | H4: 4 | I4: 6 | J4: 10 | K4: 6 | L4: 4 | M4: 2 | N4: 2 | O4: VERIFIED IN-REPO (2026-07-07): Read briefs/F-001-adhere-to-design-system.md and confirmed every current-state baseline claim exactly against source: web/src/index.css = 723 lines with 30 CSS custom-property definitions and dual theming (:root dark default + [data-theme='light'] + @media prefers-color-scheme:light); exactly 143 className= usages across 22 .tsx files; five independent feature areas (diagnostics, raweditor, settings, users, workspaces under web/src/features/); exactly three shared components (DangerConfirm, ErrorBanner, SetNotSetBadge in web/src/components/). ANALOGOUS INDUSTRY BENCHMARKS (WebSearch 2026-07-07, general-category / low project-specificity): Sparkbox "Value of Design Systems" (dev efficiency ~47%), Figma internal (34% faster task completion with system), Atlassian (up to 65% dev-time reduction), and ROI syntheses (lollypop.design, netguru, Smashing Magazine 2022) citing 135-170% 5-yr ROI and ~34% of dev cycles spent recreating components. COULD NOT VERIFY: Claude Design project at https://claude.ai/design/p/4c97b85d-5482-401b-b1b3-12df2a9d8d66 returned HTTP 403 (auth-gated) - its actual contents (tokens vs. full component set, light+dark coverage, mapping to console patterns) remain unverified; claude_design MCP re-import/sync cadence unverified. NO PROJECT-SPECIFIC DEMAND EVIDENCE: per the environment limitation, no support-ticket system, operator interviews, or usage-analytics dashboard exists for this internal tool - operator pain and payoff magnitude are unmeasured. Internal operator base size unconfirmed; October 2026 GTM hard-vs-soft status unconfirmed. | P4: REACH=5 - the console is a staff-only operator tool where the target-user population IS the internal operator base; every operator works across all five feature areas and is exposed to the governing design system on essentially every session (>70% of target users in core daily workflows). Small absolute audience does not lower the target-population fraction, which the anchor measures. USER_VALUE=2 - scored for the actual users (operators), not developers. Visual/interaction inconsistency is a coherence/cosmetic issue with an easy workaround (operators complete their jobs on the current surface); there is zero evidence of measurable operator task-pain (no tickets/interviews/analytics). Honestly minor convenience, not removal of a frequent significant pain - resisting the temptation to score the developer/maintenance benefit here (that belongs to business_value). BUSINESS_VALUE=3 - the credible payoff is a cost/velocity play (reusable tokens+components lowering per-screen build/change cost and styling-maintenance churn), which the anchor rates as a measurable effect on cost. Analogous benchmarks support a real cost/velocity effect, so this clears 2; but it is NOT a revenue/expansion/churn driver (internal, non-customer-facing tool) so it does not reach 4, and the absolute cost base is small (5 areas, 3 shared components, 723-line CSS). Landed at the low end of 3. TIME_SENSITIVITY=3 - October 2026 GTM is ~3 months out and the retrofit surface compounds with every ad-hoc screen shipped before adoption, giving a meaningful advantage to shipping this year (anchor 3). Withheld 4 (references a competitive/market window, whereas this is internal-readiness, and the GTM is an unconfirmed soft target); withheld 5 (no confirmed hard gate). CONFIDENCE=2 - the current-state baseline is fully verified and there are multiple dated analogous benchmarks, but the two most value-determining legs lack project-specific evidence: (a) operator pain (user_value) rests on codebase observation + conviction with no tickets/interviews/analytics, and (b) payoff magnitude for THIS small console rests only on general-category benchmarks the brief itself flags as low-specificity. The design system to be adopted could not be inspected (403). Per the no-inflation rule, honest value + confidence=2 is the correct encoding; did not round up to 3 because the benchmarks argue the category, not this tool. [scale-migration 2026-07-11] input scores remapped x2 (5-pt -> 10-pt migration); severity unchanged (1-5) | Q4: =IF(V4="Defect","",IF(COUNT(G4:K4)<5,"",ROUND(G4*Config!$B$4+H4*Config!$B$5+I4*Config!$B$6+J4*Config!$B$7+K4*Config!$B$8,2))) -> 7.1 | R4: =IF(L4="","",VLOOKUP(L4,Config!$A$12:$B$21,2,0)) -> 0.65 | S4: =IF(N4="","",VLOOKUP(N4,Config!$D$12:$E$21,2,0)) -> 1 | T4: =IF(V4="Defect",IF(OR(X4="",G4="",R4=""),"",ROUND(MIN(100,VLOOKUP(X4,Config!$G$12:$H$16,2,0)*VLOOKUP(G4,Config!$I$12:$J$21,2,0)*R4),1)),IF(OR(Q4="",R4="",S4="",M4=""),"",ROUND(MIN(100,Q4*R4*S4/M4*20),1))) -> 46.2 | U4: =IF(T4="","",RANK(T4,$T$4:$T$52)) -> 2 | V4: Feature
A5: F-002 | B5: Set a customer specific system prompt | C5: briefs/F-002-customer-system-prompt.md | D5: Prioritized | E5: Market Research Agent | F5: 2026-07-07 | G5: 6 | H5: 6 | I5: 4 | J5: 8 | K5: 6 | L5: 4 | M5: 4 | N5: 4 | O5: VERIFIED INTERNAL (repo read 2026-07-07): (1) web/src/features/workspaces/WorkspaceSettings.tsx lines 347-354 - the per-workspace "System prompt (blank = inherit)" textarea exists today; there is no above-workspace scope, confirming the "no baseline mechanism" problem statement. (2) bff/src/engine/mappers.ts lines 64-82 (WORKSPACE_FIELD_MAP) - systemPrompt maps 1:1 to a single engine field openAiPrompt; there is literally one prompt field per workspace and no native base+workspace layering, confirming the brief's central open question that a tamper-proof/enforced baseline is NOT achievable through this channel. (3) docs/anythingllm-surface.md lines 197-234 - confirms /system/default-system-prompt (native instance-level default) is session-auth-only and a "hard boundary at the API layer," unreachable under the console's API-key custody model; the console-managed fan-out route is the only option. All three brief leads re-verified as accurate. ANALOGOUS EXTERNAL (WebSearch 2026-07-07, directional only): Technavio - Enterprise Prompt Management Platforms market +USD 2.44B 2026-2030 at 32.5% CAGR; Gartner-cited AI-governance-platform spend ~USD 492M in 2026 rising past USD 1B by 2030; market shifting toward structured prompt governance and centralized control. These establish that centralized prompt/guardrail governance is a real, growing enterprise need. COUNTER-EVIDENCE: industry best-practice for real enforcement is a gateway-plus-guardrails architecture (policy enforced OUTSIDE the model call), not single-prompt-field storage (Galileo/Maxim/CSA 2025-2026) - corroborating that F-002's single-field approach is best-effort, not true enforcement. COULD NOT VERIFY: no support-ticket system, sales CRM, or usage-analytics dashboard exists for this internal tool, so zero direct demand signal for THIS feature; the brief itself states no discovery scan was run. Workspaces-per-customer count (bounds reach/effort) is unverifiable - an open question in the brief. The "governance as a selling point" business claim is entirely unverified against any sales evidence. | P5: REACH (3): Scored against the STAFF OPERATORS who configure the feature (the console is staff-only per surface doc; customers never touch it), not the end-user chat population whose experience the prompt shapes. Absolute operator headcount is small and the config action is infrequent/high-leverage, but establishing a baseline persona/guardrail is a task essentially every customer onboarding would touch - "regular use" within the operator setup workflow, landing at the 15-40% regular-use anchor. Note: if scored against the effect population (every end-user chat across all workspaces) it would be 5; deliberately not, because the anchor measures the feature's USERS and this is a configuration control. USER_VALUE (3): The workaround exists today and is clumsy - manually re-typing the same baseline into each workspace's systemPrompt textarea and policing drift by hand (verified the textarea is the only mechanism). F-002 removes that clumsiness = solid 3. Not 4 because (a) pain frequency scales with workspaces-per-customer, which is unknown, and (b) the "safety guardrail" job-to-be-done is only partially delivered - the verified single-field engine model means the baseline can be silently clobbered by a per-workspace edit, so the strongest value claim (an enforced guardrail) is not realizable through this channel. BUSINESS_VALUE (2): Internal operator tool; revenue/retention effect is indirect. Industry data shows governance is a growing differentiator, but there is no CRM/sales evidence customers ask for it (brief admits this), and the enforcement gap weakens the "governance selling point." Indirect/small effect = 2, not 3, because a measurable conversion/retention effect is asserted, not evidenced. TIME_SENSITIVITY (3): October 2026 GTM is ~3 months out but a SOFT internal readiness target, not a hard external deadline (no regulation/contract binds this feature), so not 4 or 5. The genuine pressure is the compounding-retrofit argument (prompts set before this exists must be retrofitted later) - real but modest. "Meaningful advantage to shipping this year" = 3. CONFIDENCE (2): Structural/feasibility facts are strongly verified in-repo, but every VALUE score rests on reasoning plus analogous industry benchmarks, not on any direct demand data for this feature - inaccessible by environment constraint and ungathered by admission. Per the cap rule and honest thinness, confidence is 2 (single-data-point/analogous-anecdote tier), not 3. [scale-migration 2026-07-11] input scores remapped x2 (5-pt -> 10-pt migration); severity unchanged (1-5) || [Human ruling 2026-07-13, resolves strategic-alignment flag] BUNDLED with F-003: rank as one sequenced initiative (F-002 first, then F-003), not two independent items. Take/defer the bundle as a unit at the bundle's position. | Q5: =IF(V5="Defect","",IF(COUNT(G5:K5)<5,"",ROUND(G5*Config!$B$4+H5*Config!$B$5+I5*Config!$B$6+J5*Config!$B$7+K5*Config!$B$8,2))) -> 5.9 | R5: =IF(L5="","",VLOOKUP(L5,Config!$A$12:$B$21,2,0)) -> 0.65 | S5: =IF(N5="","",VLOOKUP(N5,Config!$D$12:$E$21,2,0)) -> 0.9 | T5: =IF(V5="Defect",IF(OR(X5="",G5="",R5=""),"",ROUND(MIN(100,VLOOKUP(X5,Config!$G$12:$H$16,2,0)*VLOOKUP(G5,Config!$I$12:$J$21,2,0)*R5),1)),IF(OR(Q5="",R5="",S5="",M5=""),"",ROUND(MIN(100,Q5*R5*S5/M5*20),1))) -> 17.3 | U5: =IF(T5="","",RANK(T5,$T$4:$T$52)) -> 10 | V5: Feature
A6: F-003 | B6: Set a workspace level system prompt | C6: briefs/F-003-workspace-system-prompt.md | D6: Prioritized | E6: Market Research Agent | F6: 2026-07-07 | G6: 6 | H6: 6 | I6: 4 | J6: 10 | K6: 6 | L6: 4 | M6: 4 | N6: 2 | O6: Re-verified in-repo 2026-07-07: web/src/features/workspaces/WorkspaceSettings.tsx ~347-354 (lone 'System prompt (blank=inherit)' textarea); bff/src/engine/mappers.ts:74,104 + engine-types.ts:17,41 (systemPrompt->single engine openAiPrompt, no native layering); docs/anythingllm-surface.md:58,214,216 (one prompt field; native Default System Prompt/Prompt Variables session-auth = out-of-scope holds); specs/F-002-customer-system-prompt.md (baseline+sentinel/remainder/drift model, reserves per-workspace prompting for F-003; F-002 spec exists but not yet built); DangerConfirm.tsx/ErrorBanner.tsx exist; REQ-098 specs/admin-console.md:966. Rubric sheet3. No support/CRM/analytics or discovery-scan signal (internal tool). | P6: reach=3 (<25 staff operators; workspace-prompt config regular but infrequent, per F-002 logic); user_value=3 (removes clumsy manual baseline/workspace reconciliation on one opaque field, but pain contingent on unbuilt F-002 and unmeasured); business_value=2 (internal tool, indirect governance-completeness value, no sales evidence); time_sensitivity=3 (soft Oct-2026 GTM, compounding retrofit, no hard deadline); confidence=2 (structural facts verified in-repo but all value scores rest on conviction, no demand data/benchmark, plus F-002 dependency). [scale-migration 2026-07-11] input scores remapped x2 (5-pt -> 10-pt migration); severity unchanged (1-5) || [Human ruling 2026-07-13, resolves strategic-alignment flag] BUNDLED with F-002: rank as one sequenced initiative (F-002 baseline model first, then F-003), not two independent items. Take/defer the bundle as a unit at the bundle's position. | Q6: =IF(V6="Defect","",IF(COUNT(G6:K6)<5,"",ROUND(G6*Config!$B$4+H6*Config!$B$5+I6*Config!$B$6+J6*Config!$B$7+K6*Config!$B$8,2))) -> 6.3 | R6: =IF(L6="","",VLOOKUP(L6,Config!$A$12:$B$21,2,0)) -> 0.65 | S6: =IF(N6="","",VLOOKUP(N6,Config!$D$12:$E$21,2,0)) -> 1 | T6: =IF(V6="Defect",IF(OR(X6="",G6="",R6=""),"",ROUND(MIN(100,VLOOKUP(X6,Config!$G$12:$H$16,2,0)*VLOOKUP(G6,Config!$I$12:$J$21,2,0)*R6),1)),IF(OR(Q6="",R6="",S6="",M6=""),"",ROUND(MIN(100,Q6*R6*S6/M6*20),1))) -> 20.5 | U6: =IF(T6="","",RANK(T6,$T$4:$T$52)) -> 9 | V6: Feature
A7: F-004 | B7: Implement a proper production ready eventbus to replace the inproc bus currently in use | C7: briefs/F-004-production-event-bus.md | D7: Implemented | E7: Market Research Agent | F7: 2026-07-07 | G7: 8 | H7: 8 | I7: 6 | J7: 10 | K7: 6 | L7: 4 | M7: 8 | N7: 6 | O7: bff/src/config.ts:50 (inproc default); bff/src/events/bus.ts:16-34 (InProcessBus default + OutboxRelayBus enqueue-only stub, 'later slice' comment); bff/src/store/repositories/outbox.repo.ts:34 listUnpublished has zero callers (no drain worker); grep: no .emitter.on / getEventBus consumers = zero subscribers; bff/src/events/catalog.ts + emitter.ts (contract built); docs/design/04-cross-cutting.md:74-76 & 06-risks.md:70 (relay deferred/open); specs/admin-console.md REQ-029; no incident/demand/analytics signal in-repo. | P7: [Human] A robust stable reliable eventbus is needed for actual customer use and I may as well be developing on a real eventbus as soon as possible. || [Research 2026-07-07] reach=4 (delivery backbone for the entire admin.* event spine (17 event types, core cross-cutting) but consumer population latent/empty today so not 5); user_value=4 (unlocks a currently-impossible JTBD: durable cross-process at-least-once delivery + audit reliability, held below 5 since no consumer verified waiting); business_value=3 (production-readiness/compliance + tech-debt avoidance, no evidenced revenue/churn driver, internal infra); time_sensitivity=3 (GTM-linked ~3mo window but inproc is deployable and no consumer proven blocked); confidence=2 (structural gap validated with file:line citations but value/demand/urgency rest on conviction, zero usage/incident/demand evidence). [scale-migration 2026-07-11] input scores remapped x2 (5-pt -> 10-pt migration); severity unchanged (1-5) || [Human ruling 2026-07-13, resolves strategic-alignment flag] TOP PRIORITY override: rank-7 formula placement is overridden due to architectural significance — all features with strategic importance must build on this eventbus, so it precedes them in implementation order regardless of its effort-divided score. Scores left honest/unchanged; override lives here and in the run report. [implement-spec 2026-07-19] implemented per specs/F-004-production-event-bus.md (rev 11); branch feat/f-004-event-bus-delivery; full suite green (bff 1229, e2e relay 11, tsc clean). Pipeline: architect+migration+qa+impl; qa/unit/e2e verification; security PASS-WITH-NOTES + code-review BLOCK cleared; perf FAIL fixed (eligibility query O(backlog)); refactor+docs. Follow-up: D-006 peer auth (GH #16); deploy notes F3 (/ready bind) / F4 (SSRF allowlist). | Q7: =IF(V7="Defect","",IF(COUNT(G7:K7)<5,"",ROUND(G7*Config!$B$4+H7*Config!$B$5+I7*Config!$B$6+J7*Config!$B$7+K7*Config!$B$8,2))) -> 7.7 | R7: =IF(L7="","",VLOOKUP(L7,Config!$A$12:$B$21,2,0)) -> 0.65 | S7: =IF(N7="","",VLOOKUP(N7,Config!$D$12:$E$21,2,0)) -> 0.8 | T7: =IF(V7="Defect",IF(OR(X7="",G7="",R7=""),"",ROUND(MIN(100,VLOOKUP(X7,Config!$G$12:$H$16,2,0)*VLOOKUP(G7,Config!$I$12:$J$21,2,0)*R7),1)),IF(OR(Q7="",R7="",S7="",M7=""),"",ROUND(MIN(100,Q7*R7*S7/M7*20),1))) -> 10 | U7: =IF(T7="","",RANK(T7,$T$4:$T$52)) -> 12 | V7: Feature
A8: D-001 | B8: The color of the background for each providers expandable panel in the LLM settings does not provide enough contrast to make the actual fields the user has to enter data into impossible to see. The panel background colors should be a lighter grey color that aligns with the colors in the design system. | C8: https://github.com/dispatch-derek/admin-console/issues/5 | D8: Prioritized | E8: Hybrid | F8: 46214 | G8: 8 | H8: 3 | I8: 2 | J8: 4 | K8: 6 | L8: 8 | M8: 2 | N8: 2 | O8: GitHub issue #5 (dispatch-derek/admin-console), fetched via gh issue view — title 'UI Panels backgrounds do not provide enough contrast against the black background to make the data entry fields visible to the user'; body confirms fields invisible except on focus; Open, no comments/screenshots/second reporter. Code inspection: web/src/design-system/tokens/colors.css lines 40-43,56 — dark theme (default) sets --theme-bg-primary, --theme-bg-container, and --theme-settings-input-bg to the identical #0e0f0f; web/src/index.css lines 13-28,340-386 confirm panel body has no background override so it inherits page bg; web/src/design-system/components/Field.module.css lines 15-32 confirm shared .control class (every Input/Select/Textarea) has border:none and only gains a visible outline on :focus -- matches reported symptom exactly. [data-theme=light] block (colors.css lines 82-118) shows light theme is unaffected (--theme-settings-input-bg #edf2fa vs --theme-bg-container #f9fbfd, clear contrast). web/src/features/settings/SettingsPage.tsx lines 284-350 confirms provider groups render generically with no per-provider styling branch -> affects all ~30+ providers and all provider-group screens (LLM, embedding, vector DB, TTS, STT) uniformly, not just 'LLM settings' as the ticket title implies. docs/anythingllm-surface.md sec2 confirms provider config is an admin-console-exclusive, instance-wide function every operator must pass through at least once during provisioning/reconfiguration, but is a setup screen, not a daily-use screen. | P8: Reach revised 5->4: defect is a shared-token collision affecting 100% of provider panels/fields uniformly in dark theme (the default), so nearly every operator opening any expandable settings panel without switching to light theme hits it on every field -- but per rubric, reach=5 requires >70% of users in CORE DAILY workflows, and this is a periodic setup/reconfiguration screen, not daily-use, so 4 ('40-70% frequently') fits better than 5. True reach is also bounded by the unmeasured dark-vs-light theme split across instances (dark is default, likely majority, but unconfirmed by analytics). Confidence=4: not speculation or a single anecdote -- traced the exact mechanism in source (identical hex tokens, border:none, no panel bg override), concrete and reproducible-from-code, consistent with the issue's stated symptoms. Capped below 5 because there is no committed/live reproduction (screenshot, second reporter, test) beyond the original reporter's unconfirmed issue and this code trace. [scale-migration 2026-07-11] input scores remapped x2 (5-pt -> 10-pt migration); severity unchanged (1-5) | Q8: =IF(V8="Defect","",IF(COUNT(G8:K8)<5,"",ROUND(G8*Config!$B$4+H8*Config!$B$5+I8*Config!$B$6+J8*Config!$B$7+K8*Config!$B$8,2))) | R8: =IF(L8="","",VLOOKUP(L8,Config!$A$12:$B$21,2,0)) -> 0.9 | S8: =IF(N8="","",VLOOKUP(N8,Config!$D$12:$E$21,2,0)) -> 1 | T8: =IF(V8="Defect",IF(OR(X8="",G8="",R8=""),"",ROUND(MIN(100,VLOOKUP(X8,Config!$G$12:$H$16,2,0)*VLOOKUP(G8,Config!$I$12:$J$21,2,0)*R8),1)),IF(OR(Q8="",R8="",S8="",M8=""),"",ROUND(MIN(100,Q8*R8*S8/M8*20),1))) -> 29.7 | U8: =IF(T8="","",RANK(T8,$T$4:$T$52)) -> 4 | V8: Defect | W8: Internal | X8: 2
A9: F-005 | B9: Per-Customer Feature Toggle Console | C9: briefs/F-005-per-customer-feature-toggle-console.md | D9: Implemented | E9: Market Research Agent | F9: 46214 | G9: 8 | H9: 8 | I9: 10 | J9: 5 | K9: 10 | L9: 4 | M9: 5 | N9: 1 | O9: Primary: briefs/F-005-per-customer-feature-toggle-console.md (Affected Users, Problem, Business Rationale, Timing, Existing Evidence sections) — brief explicitly states no usage/ticket evidence exists yet (product unshipped); reach/user_value/time_sensitivity based on brief's internal narrative only. Secondary (analogous, not company-specific): WebSearch 2026-07-11 'feature flag entitlement system usage-based billing prerequisite ROI benchmark' — Statsig 'B2B SaaS Experimentation: Feature Flags, Metrics, and ROI' (statsig.com/perspectives/b2b-saas-experiment-feature-flags); Chargebee 'Entitlement Management & Automated Feature Provisioning' (chargebee.com/entitlement-management); Salable 'Feature Flags and Entitlements: A Practical Guide' (salable.app/blog/insights/entitlements-future-feature-management) — report up to 38% higher YoY growth and ~10pt higher NDR for usage-based/entitlement-gated pricing vs flat-price peers, and 1-3% revenue leakage industry-wide from ungated features. | P9: reach=4: target population is admin-console operators (per brief), becomes near-universal once customer-facing app ships, but post-ship frequency is explicitly 'unknown' per brief -> periodic not daily, so 4 not 5. user_value=4: unlocks a wholly new job-to-be-done (no current mechanism exists) but the pain is prospective (app hasn't shipped, no operator experiences this today), so capped at 4 not 5. business_value=5: hard blocking prerequisite for a new revenue-generating product surface AND explicit foundation for a new billing model -> matches anchor 5 'opens a new segment/market'; analogous industry benchmarks support plausibility though not company-specific. time_sensitivity=5: brief states a hard blocking dependency tied to a named internal October GTM date -> matches anchor 5 'hard deadline... or closing window' (internal committed launch, not external regulation, but functions the same as a schedule gate). confidence=2: no independent evidence beyond the brief's own narrative for reach/user_value/time_sensitivity (single internal document); business_value has only analogous industry benchmarks, not company-specific proof. Per no-inflation rule, capped at 2 rather than rounded up. [scale-migration 2026-07-11] input scores remapped x2 (5-pt -> 10-pt migration); severity unchanged (1-5) | Q9: =IF(V9="Defect","",IF(COUNT(G9:K9)<5,"",ROUND(G9*Config!$B$4+H9*Config!$B$5+I9*Config!$B$6+J9*Config!$B$7+K9*Config!$B$8,2))) -> 8.1 | R9: =IF(L9="","",VLOOKUP(L9,Config!$A$12:$B$21,2,0)) -> 0.65 | S9: =IF(N9="","",VLOOKUP(N9,Config!$D$12:$E$21,2,0)) -> 1 | T9: =IF(V9="Defect",IF(OR(X9="",G9="",R9=""),"",ROUND(MIN(100,VLOOKUP(X9,Config!$G$12:$H$16,2,0)*VLOOKUP(G9,Config!$I$12:$J$21,2,0)*R9),1)),IF(OR(Q9="",R9="",S9="",M9=""),"",ROUND(MIN(100,Q9*R9*S9/M9*20),1))) -> 21.1 | U9: =IF(T9="","",RANK(T9,$T$4:$T$52)) -> 8 | V9: Feature
A10: D-002 | B10: Light-theme secondary text (--theme-text-secondary #7a7d7e) fails WCAG 2.1 AA contrast (4.15:1 < 4.5:1) on all consumers incl. F-005 provenance/label text; token is byte-pinned by F-001 gates so the fix is an F-001-scope design-system revision | C10: https://github.com/dispatch-derek/admin-console/issues/7 | D10: Prioritized | E10: Market Research Agent | F10: 2026-07-13 | G10: 5 | J10: 1 | K10: 5 | L10: 7 | M10: 2 | N10: 1 | O10: GH issue dispatch-derek/admin-console#7 (fetched via gh 2026-07-13). Token: web/src/design-system/tokens/colors.css:92 (--theme-text-secondary: #7a7d7e under [data-theme=light]; light bg-primary/bg-secondary #ffffff at :84-85); same value in light-source.css:21 and vendor/design-system/project/tokens/colors.css:92. Computed WCAG 2.1 contrast (relative luminance, sRGB linearization, (L1+0.05)/(L2+0.05)): 4.148:1 on #ffffff (fails 4.5:1 AA; matches issue's 4.15:1), 4.00:1 on #f9fbfd, 3.69:1 on #edf2fa, 3.45:1 on #eaeaea. Consumers (grep 2026-07-13): 27 declarations in web/src/index.css incl. F-005 surfaces .feature-customer-label:672, .feature-counts:680, .feature-category-tag/.feature-row-meta:722-726, .feature-empty-help:747; plus Badge.module.css:35, Table.module.css:25, Field.module.css:62, Toggle.module.css:90, PageHeader.module.css:31. Byte-pin verified: adopted-tokens.test.ts:27 (byte-for-byte vs vendored reference, REQ-F001-017), tests/gates/vendor-immutability.test.ts:38 (pinned hashes), dual-theme-harness.test.ts:46 (pins light value, REQ-F001-052). OS-light exposure: web/src/bridge/prefers-color-scheme.css:10-20 auto-applies #7a7d7e for OS-light users with no data-theme. | P10: Reach 5 (15-25% regular use): the token styles secondary text on virtually every screen (27 index.css consumers + 5 shared DS components, incl. F-005's core provenance/label text), so any light-theme operator encounters it constantly in daily workflows — but only light-theme users are affected. Dark is the :root default; light requires OS light preference (auto via bridge) or explicit data-theme=light, the theme split among staff operators is unmeasured (no analytics), and operator populations commonly skew dark. Honest mid-band estimate 15-25%, not inflated to 6+ without theme-adoption data; the impact is also graduated (borderline 4.15:1, most harmful to low-vision users) rather than a functional break. Confidence 7 (good data, known gaps): the defect is deterministically reproduced — independently recomputed contrast ratios (4.148:1 on white, worse on other light surfaces) and verified the byte-pin constraint in the gate test sources, and the issue documents an empirically reverted fix attempt — but the reach side rests on zero measurement of light-theme share among operators, which keeps it below 8. | Q10: =IF(V10="Defect","",IF(COUNT(G10:K10)<5,"",ROUND(G10*Config!$B$4+H10*Config!$B$5+I10*Config!$B$6+J10*Config!$B$7+K10*Config!$B$8,2))) | R10: =IF(L10="","",VLOOKUP(L10,Config!$A$12:$B$21,2,0)) -> 0.85 | S10: =IF(N10="","",VLOOKUP(N10,Config!$D$12:$E$21,2,0)) -> 1 | T10: =IF(V10="Defect",IF(OR(X10="",G10="",R10=""),"",ROUND(MIN(100,VLOOKUP(X10,Config!$G$12:$H$16,2,0)*VLOOKUP(G10,Config!$I$12:$J$21,2,0)*R10),1)),IF(OR(Q10="",R10="",S10="",M10=""),"",ROUND(MIN(100,Q10*R10*S10/M10*20),1))) -> 24.2 | U10: =IF(T10="","",RANK(T10,$T$4:$T$52)) -> 5 | V10: Defect | W10: Internal | X10: 2
A11: F-006 | B11: Local-first per-workspace LLM observability (usage, performance, resource load) | C11: briefs/F-006-local-first-workspace-llm-observability.md | D11: Prioritized | E11: Hybrid | F11: 2026-07-19 | G11: 6 | H11: 7 | I11: 6 | J11: 7 | K11: 4 | L11: 5 | M11: 6 | N11: 5 | O11: Re-verified in-repo 2026-07-19 (first-hand): DiagnosticsPage.tsx:1-75 (2 instance-scoped facts, 0 per-workspace/time-series); relay/metrics.ts:1-68 (relay-delivery scope only); bff+web package.json (zero telemetry/charting deps); oversight.service.ts:13-27 + mappers.ts:229-231 + engine-types.ts:97-105 (chats passed as opaque unknown[], 0 metric fields parsed); events/catalog.ts AdminEventName union = 21 config/CRUD names, none usage/perf (brief said 20; substance holds). Carried from brief (not re-fetched): engine event_logs session-auth-only + workspace_chats blob-embedded timing (docs/anythingllm-surface.md:205-219); Ollama /api/generate 6 metric fields + /api/ps (ollama docs). Human-supplied: fleet <5 appliances; three-consumer framing; zero-cloud constraint (PO 2026-07-19). | Addendum 2026-07-19: brief Business Rationale revised — PO verbatim ruling that observability data benefits revenue via customer-facing reports/dashboards (briefs/F-006-local-first-workspace-llm-observability.md, 'Product-owner addition, 2026-07-19' + packaged/paid-vs-included Open Question). | P11: reach=6 (breadth-vs-frequency tension: all 3 personas exposed per deployment, but consumption episodic — capacity periodic, reporting periodic, troubleshooting incident-driven; breadth reading could argue 7). user_value=7 (troubleshooting has NO workaround — data gone once event passes; capacity is wait-for-complaint; customer reporting is a new JTBD nudging 8, held at 7 as value diffuse across episodic cases). business_value=5 (billing/metering excluded by PO so revenue argument off the table; support/ops cost + reporting satisfaction, indirect and small at <5 appliances; GTM-gate not established — brief's own ops-minimum question). time_sensitivity=4 (no date/window supplied; GTM coupling real but unquantified — re-score if launch date lands). confidence=5 (gap proven multi-source in-repo; value framing single-stakeholder, usage data structurally unavailable at this fleet size; unresolved metric-capture point bleeds feasibility uncertainty into value confidence). | [re-score 2026-07-19, Hybrid] business_value 5->6: PO ruling reframes billing exclusion — metering out, but customer-facing reports/dashboards = revenue-benefiting retention capability (anchor 6 'conversion, retention, or cost'); held below 7+ (single-stakeholder hypothesis, no adoption/willingness-to-pay evidence, packaged-vs-included unresolved). Confidence unchanged at 5. | Human override 2026-07-19: Deferred -> Prioritized by product owner (revenue-via-reporting thesis); prioritizer's sequencing caveats stand (capture point unresolved, GTM undated). | Q11: =IF(V11="Defect","",IF(COUNT(G11:K11)<5,"",ROUND(G11*Config!$B$4+H11*Config!$B$5+I11*Config!$B$6+J11*Config!$B$7+K11*Config!$B$8,2))) -> 6.25 | R11: =IF(L11="","",VLOOKUP(L11,Config!$A$12:$B$21,2,0)) -> 0.73 | S11: =IF(N11="","",VLOOKUP(N11,Config!$D$12:$E$21,2,0)) -> 0.85 | T11: =IF(V11="Defect",IF(OR(X11="",G11="",R11=""),"",ROUND(MIN(100,VLOOKUP(X11,Config!$G$12:$H$16,2,0)*VLOOKUP(G11,Config!$I$12:$J$21,2,0)*R11),1)),IF(OR(Q11="",R11="",S11="",M11=""),"",ROUND(MIN(100,Q11*R11*S11/M11*20),1))) -> 12.9 | U11: =IF(T11="","",RANK(T11,$T$4:$T$52)) -> 11 | V11: Feature
A12: D-003 | B12: Workspace chat history page is leaking json of the chat history onto the page vs laying out the data in a tabular format for human viewing. | C12: https://github.com/dispatch-derek/admin-console/issues/9 | D12: Prioritized | E12: Market Research Agent | F12: 2026-07-15 | G12: 6 | J12: 5 | L12: 7 | O12: GH issue dispatch-derek/admin-console#9 (fetched via gh 2026-07-15): reporter states the Workspace Chats screen renders raw JSON of chat history instead of a tabular layout and 'fails in the same way no matter which workspace you choose' — includes a full-page screenshot (committed live reproduction). Code inspection confirms mechanism deterministically: web/src/features/users/ChatOversight.tsx:75-81 renders every record as <li><pre>{JSON.stringify(chat, null, 2)}</pre></li> with no field mapping — the chats array is typed unknown[] (:17) and dumped verbatim. Rendering is workspace-independent (the Select filter at :62-73 only changes which records load, not how they render), matching the reporter's 'every workspace' claim. Chat oversight is a primary console surface (REQ-051, §6.6), listed in the main sidebar as 'Workspace Chats'. | P12: Reach 6 (15-40% regular use): a primary listed nav surface that fails completely (raw JSON, not degraded) for 100% of operators who open it, on every workspace — but chat oversight is one of several staff functions and not every operator uses it daily, and there is no analytics on the oversight-user share, so held at 6 rather than a daily-workflow 8+. Confidence 7 (good data, known gaps): defect is deterministically reproduced from source (literal JSON.stringify render) AND has a committed screenshot + reporter confirmation in issue #9 — stronger than a code trace alone (cf. D-001 conf 4, which lacked live repro); capped below 8 only because the reach-share estimate rests on no operator-usage measurement. Severity 5 is human triage-owned; not modified by this role. | Q12: =IF(V12="Defect","",IF(COUNT(G12:K12)<5,"",ROUND(G12*Config!$B$4+H12*Config!$B$5+I12*Config!$B$6+J12*Config!$B$7+K12*Config!$B$8,2))) | R12: =IF(L12="","",VLOOKUP(L12,Config!$A$12:$B$21,2,0)) -> 0.85 | S12: =IF(N12="","",VLOOKUP(N12,Config!$D$12:$E$21,2,0)) | T12: =IF(V12="Defect",IF(OR(X12="",G12="",R12=""),"",ROUND(MIN(100,VLOOKUP(X12,Config!$G$12:$H$16,2,0)*VLOOKUP(G12,Config!$I$12:$J$21,2,0)*R12),1)),IF(OR(Q12="",R12="",S12="",M12=""),"",ROUND(MIN(100,Q12*R12*S12/M12*20),1))) -> 85 | U12: =IF(T12="","",RANK(T12,$T$4:$T$52)) -> 1 | V12: Defect | W12: Internal | X12: 5
A13: F-007 | B13: Multi-language and number format internationalization support in the user interface | C13: briefs/F-007-ui-internationalization.md | D13: Prioritized | E13: Market Research Agent | F13: 2026-07-19 | G13: 2 | H13: 6 | I13: 8 | J13: 7 | K13: 3 | L13: 4 | M13: 2 | N13: 2 | O13: Re-verified 2026-07-19: web/package.json zero i18n deps (react, react-dom, @phosphor-icons only); no locale/i18n/.po files under web/; exactly 2 default-locale format sites (DiagnosticsPage.tsx:49, BaselineEditor.tsx:110); zero explicit-Intl/navigator.language/Accept-Language across 111 TS/TSX files; 56 inline JSX text nodes matched across 21 tsx files (confirms brief's >=48 lower bound). Upstream: anything-llm frontend/src/locales ~26 locale folders + translation scripts (verified); upstream issue #1371 non-English UI request (verified). Zero inbound localization requests for this fork (no ticketing channel exists; nothing in docs/README/CHANGELOG). | P13: reach=2 (population-share floor: ~0% observed non-English operators, prospective fraction unsized/undated; DISSENT: broad whole-UI capability arguably higher — a dated market-entry commitment should trigger reach re-score upward). user_value=6 (real per-session friction for non-English operator, clumsy-not-blocking workaround). business_value=8 (table-stakes enabler of stated market expansion; not 9-10 — enabler, not the market-opener, unsized). time_sensitivity=3 (GTM-tied but NO date supplied; value decays slowly; re-score if dates arrive). confidence=4 (current-state gap code-verified, but demand hypothesis rests on upstream analogs only; zero fork-specific demand signals). | Q13: =IF(V13="Defect","",IF(COUNT(G13:K13)<5,"",ROUND(G13*Config!$B$4+H13*Config!$B$5+I13*Config!$B$6+J13*Config!$B$7+K13*Config!$B$8,2))) -> 5.6 | R13: =IF(L13="","",VLOOKUP(L13,Config!$A$12:$B$21,2,0)) -> 0.65 | S13: =IF(N13="","",VLOOKUP(N13,Config!$D$12:$E$21,2,0)) -> 1 | T13: =IF(V13="Defect",IF(OR(X13="",G13="",R13=""),"",ROUND(MIN(100,VLOOKUP(X13,Config!$G$12:$H$16,2,0)*VLOOKUP(G13,Config!$I$12:$J$21,2,0)*R13),1)),IF(OR(Q13="",R13="",S13="",M13=""),"",ROUND(MIN(100,Q13*R13*S13/M13*20),1))) -> 36.4 | U13: =IF(T13="","",RANK(T13,$T$4:$T$52)) -> 3 | V13: Feature
A14: D-004 | B14: Lefthand side menu in UI has a visible vertical scroll bar but the scroll bar should always be invisible to the user. The menu should still be vertically scrollable with the mousewheel even though the scrollbar is invisible. Refer to the way that this is handled in the AnythingLLM web frontend for a guide to what is needed for UX and design of the lefthand side menu. | D14: Prioritized | E14: Market Research Agent | F14: 2026-07-15 | G14: 6 | J14: 2 | L14: 6 | O14: Code inspection (2026-07-15): web/src/index.css:103-107 — .ac-sidebar-nav sets overflow-y:auto with NO scrollbar-hiding declarations (no scrollbar-width:none, no ::-webkit-scrollbar{display:none}), so a native vertical scrollbar renders whenever the nav content exceeds viewport height. The sidebar carries ~15 items across sections (App.tsx nav), which overflows at common laptop heights. Reference behavior for the intended fix exists in the AnythingLLM web frontend (scrollbar hidden, wheel-scroll retained), per the reporter. No GH ticket / brief_ref and no committed screenshot — evidence is the deterministic code trace plus the reporter's description. | P14: Reach 6 (15-40% regular use): the sidebar is on every console screen (seen ~100% of the time), but the defect symptom is conditional on the nav overflowing the viewport, which depends on unmeasured operator window height/zoom; common on 13-14in laptops with this item count but not universal, so 6 not 8. Confidence 6 (deterministic repro, reach gap): the missing-rule mechanism is certain from source, but there is no live screenshot and the overflow frequency across operator viewports is unmeasured. Purely cosmetic (still wheel-scrollable) — severity 1 is human-owned and unchanged by this role. | Q14: =IF(V14="Defect","",IF(COUNT(G14:K14)<5,"",ROUND(G14*Config!$B$4+H14*Config!$B$5+I14*Config!$B$6+J14*Config!$B$7+K14*Config!$B$8,2))) | R14: =IF(L14="","",VLOOKUP(L14,Config!$A$12:$B$21,2,0)) -> 0.8 | S14: =IF(N14="","",VLOOKUP(N14,Config!$D$12:$E$21,2,0)) | T14: =IF(V14="Defect",IF(OR(X14="",G14="",R14=""),"",ROUND(MIN(100,VLOOKUP(X14,Config!$G$12:$H$16,2,0)*VLOOKUP(G14,Config!$I$12:$J$21,2,0)*R14),1)),IF(OR(Q14="",R14="",S14="",M14=""),"",ROUND(MIN(100,Q14*R14*S14/M14*20),1))) -> 8 | U14: =IF(T14="","",RANK(T14,$T$4:$T$52)) -> 14 | V14: Defect | W14: Internal | X14: 1
A15: F-008 | B15: System-wide backups on schedule | C15: briefs/F-008-system-wide-scheduled-backups.md | D15: Prioritized | E15: Market Research Agent | F15: 2026-07-19 | G15: 8 | H15: 6 | I15: 7 | J15: 10 | K15: 5 | L15: 6 | M15: 4 | N15: 7 | O15: Re-verified 2026-07-19: zero backup/restore/snapshot/VACUUM-INTO capability in admin-console AND /home/derek/git/customer-web-app (all hits unrelated: env-dump diagnostics, vitest fixtures). settings-map.ts:39-43 Ollama managed over-the-wire only; zero references to Ollama on-disk storage in either repo. db-path.ts:8 DB_PATH default data/console.db shared by BFF+relay. Manual-backup preconditions exist in TWO runbooks (F-004:86, F-005:90) — brief's 'three' is overstated, F-002 runbook has none. git log --all: zero incident/drill history (only the brief commit itself). No deployment descriptors in either repo. Brief: briefs/F-008-system-wide-scheduled-backups.md (PO scope rulings 2026-07-19 incl. Ollama + ABM/iCloud investigation). | P15: reach=8 (judgment placement: breadth maximal — 100% of users of all three apps bear continuous data-loss exposure — but anchors 9-10 reward active daily interaction which a background DR capability lacks; pure-breadth reading defends 9-10, reviewer may override either way). user_value=6 (catastrophic-but-latent pain; zero experienced loss events; 7-8 require frequent pain). business_value=7 (production-readiness/GTM enabler + tail-risk defense; GTM milestone unconfirmed, no incident/contract evidence for higher). time_sensitivity=5 (undated production gate; rises 6-7 if near-term GTM date confirmed). confidence=6 (gap existence code-verified ~certain; value magnitude/urgency directional with no incident history; anchored to the weaker evidence class). DISSENT: if PO confirms hard near-term GTM gate, business_value and time_sensitivity are under-scored - re-score then. | Q15: =IF(V15="Defect","",IF(COUNT(G15:K15)<5,"",ROUND(G15*Config!$B$4+H15*Config!$B$5+I15*Config!$B$6+J15*Config!$B$7+K15*Config!$B$8,2))) -> 7.35 | R15: =IF(L15="","",VLOOKUP(L15,Config!$A$12:$B$21,2,0)) -> 0.8 | S15: =IF(N15="","",VLOOKUP(N15,Config!$D$12:$E$21,2,0)) -> 0.75 | T15: =IF(V15="Defect",IF(OR(X15="",G15="",R15=""),"",ROUND(MIN(100,VLOOKUP(X15,Config!$G$12:$H$16,2,0)*VLOOKUP(G15,Config!$I$12:$J$21,2,0)*R15),1)),IF(OR(Q15="",R15="",S15="",M15=""),"",ROUND(MIN(100,Q15*R15*S15/M15*20),1))) -> 22.1 | U15: =IF(T15="","",RANK(T15,$T$4:$T$52)) -> 6 | V15: Feature | W15: Internal
A16: D-005 | B16: Dead code: engine adapter envDump() and its GET /v1/system/env-dump wrapper are unused and point at a misleading AnythingLLM endpoint. That endpoint is a 'dump settings to file' action that replies with bare status text 'OK' (a no-op outside production), never JSON. The diagnostics 500 fix repointed getEnvDump() to adapter.getSystem(), so envDump() now survives only as ~8 test mocks. Remove EngineAdapter.envDump, HttpEngineAdapter.envDump, and the stale mocks. | C16: https://github.com/dispatch-derek/admin-console/issues/10 | D16: Prioritized | E16: Market Research Agent | F16: 2026-07-19 | G16: 1 | J16: 5 | L16: 10 | M16: 1 | N16: 1 | O16: GH issue dispatch-derek/admin-console#10 (gh issue view 10); re-verified 2026-07-19 by code inspection: envDump interface bff/src/engine/adapter.ts:57, impl :242-245 wrapping /system/env-dump (:243); grep '\.envDump(' bff/src -> 0 callers; survives as 11 mock refs across 9 test files (bff/test/routes/*, bff/test/services/baseline.service.test.ts); fix already landed at bff/src/services/settings.service.ts:341 (getEnvDump -> adapter.getSystem()). | P16: reach=1 (anchor 1 'rare edge case': dead code, zero runtime callers, 0% of operators affected; original 500 already fixed by repointing getEnvDump). confidence=10 (anchor 10 'validated': exhaustive static verification of a typed codebase — whole-tree grep for call sites yields none; mocks and landed fix confirmed at cited lines). | Q16: =IF(V16="Defect","",IF(COUNT(G16:K16)<5,"",ROUND(G16*Config!$B$4+H16*Config!$B$5+I16*Config!$B$6+J16*Config!$B$7+K16*Config!$B$8,2))) | R16: =IF(L16="","",VLOOKUP(L16,Config!$A$12:$B$21,2,0)) -> 1 | S16: =IF(N16="","",VLOOKUP(N16,Config!$D$12:$E$21,2,0)) -> 1 | T16: =IF(V16="Defect",IF(OR(X16="",G16="",R16=""),"",ROUND(MIN(100,VLOOKUP(X16,Config!$G$12:$H$16,2,0)*VLOOKUP(G16,Config!$I$12:$J$21,2,0)*R16),1)),IF(OR(Q16="",R16="",S16="",M16=""),"",ROUND(MIN(100,Q16*R16*S16/M16*20),1))) -> 7.5 | U16: =IF(T16="","",RANK(T16,$T$4:$T$52)) -> 15 | V16: Defect | W16: Internal | X16: 1
A17: D-006 | B17: Event relay delivers admin.* envelopes to peers without authentication or TLS enforcement (F-004 security review F2). bff/src/relay/http-peer-transport.ts POSTs admin.* event envelopes to EVENT_BUS_URL peers with no HMAC/mTLS body auth and no https enforcement; http:// peers accepted without scheme validation. Confidentiality/integrity exposure of the admin event stream + forged-event injection risk at consumers. Blast radius bounded by operator-controlled config. Follow-up hardening: HMAC signing or mTLS + require https:// peers in production. | C17: https://github.com/dispatch-derek/admin-console/issues/16 | D17: Prioritized | E17: Market Research Agent | F17: 2026-07-19 | G17: 1 | L17: 9 | O17: Re-verified 2026-07-19 (main, F-004 merged via PR #17): bff/src/relay/http-peer-transport.ts:60-67 POST sends only content-type + x-event-delivery-id, no HMAC/signature/bearer/mTLS; bff/src/relay/config.ts:13-17 EVENT_BUS_URL parsed with no scheme validation (http:// accepted); bff/.env.example:24-25 and bff/.env:25 EVENT_BUS_MODE=inproc, EVENT_BUS_URL empty -> HttpPeerTransport inactive in known deployment; bff/src/config.ts:40-56 bus/inproc gating; security/F-004-review.md finding F2 [Medium] independent confirmation; GH issue #16. | P17: [intake 2026-07-19] Logged from F-004 Phase 7 security review (security/F-004-review.md, finding F2 [Medium]). Accepted for GTM: peers are operator-controlled endpoints on a trusted network and the peer trust model was explicitly deferred by the F-004 spec. Follow-up: HMAC body signing or mTLS, plus require https:// peers when NODE_ENV=production (allow internal http:// only behind a service mesh by opt-in). See also security review F3 (/ready bind address) and F4 (outbound SSRF allowlist). GH issue #16. | [research 2026-07-19] reach=1 (anchor 1 'rare edge case': exposure requires opting into EVENT_BUS_MODE=bus + peer URLs + http/MITM-able hop; known deployment runs inproc, ~0 operators hit it today). confidence=9 (anchor 9: absent-control confirmed by direct code read at exact lines + independent security review F2; residual unknown only that no live bus-mode deployment exercises the path). Not inflating reach to compensate severity - severity (human, 2) carries the fast-track formula by design. | Q17: =IF(V17="Defect","",IF(COUNT(G17:K17)<5,"",ROUND(G17*Config!$B$4+H17*Config!$B$5+I17*Config!$B$6+J17*Config!$B$7+K17*Config!$B$8,2))) | R17: =IF(L17="","",VLOOKUP(L17,Config!$A$12:$B$21,2,0)) -> 0.95 | S17: =IF(N17="","",VLOOKUP(N17,Config!$D$12:$E$21,2,0)) | T17: =IF(V17="Defect",IF(OR(X17="",G17="",R17=""),"",ROUND(MIN(100,VLOOKUP(X17,Config!$G$12:$H$16,2,0)*VLOOKUP(G17,Config!$I$12:$J$21,2,0)*R17),1)),IF(OR(Q17="",R17="",S17="",M17=""),"",ROUND(MIN(100,Q17*R17*S17/M17*20),1))) -> 21.4 | U17: =IF(T17="","",RANK(T17,$T$4:$T$52)) -> 7 | V17: Defect | W17: Internal | X17: 2
A18: F-009 | B18: Console login for console-created admin users | C18: briefs/F-009-console-login-for-console-created-admin-users.md | D18: Prioritized | E18: Market Research Agent | F18: 2026-07-19 | G18: 4 | H18: 6 | I18: 4 | J18: 7 | K18: 9 | L18: 5 | M18: 7 | N18: 5 | O18: Re-verified in-repo 2026-07-19: bff/src/routes/auth.routes.ts:133 (login resolves only staffRepo.findByUsername); bff/src/services/user.service.ts:101-135 (createUser writes engine only, no staff row); bff/src/auth/bootstrap.ts:11-20 (single bootstrap account when staff count==0); web/src/features/ has no staff feature; web/src/api/client.ts:127,131 listStaff/createStaff unconsumed. Firsthand operator report 2026-07-19 (brief), single known deployment/operator. Product-owner timing ruling 2026-07-19: ASAP, go-to-market blocker gating multi-operator testing. | P18: Scored against console operators as target population. reach=4 ('5-15% or infrequent use'; onboarding-frequency, N=1 deployment today — 3 was arguable). user_value=6 (real pain, clumsy workaround: hand-rolled POST /api/staff + silent-failure UX; held below 7 as pain is onboarding-frequency, not frequent). business_value=4 (indirect GTM precondition, explicitly unquantified — not inflated; confidence carries the uncertainty). time_sensitivity=9 (ASAP/within-quarter window; not 10 — no external hard deadline). confidence=5 (mechanism code-verified, demand side N=1, no tickets/analytics). | Human sign-off 2026-07-19 (risk>=9 flag review): risk revised 10 -> 5 by product owner; flag cleared; status -> Prioritized. | Q18: =IF(V18="Defect","",IF(COUNT(G18:K18)<5,"",ROUND(G18*Config!$B$4+H18*Config!$B$5+I18*Config!$B$6+J18*Config!$B$7+K18*Config!$B$8,2))) -> 5.6 | R18: =IF(L18="","",VLOOKUP(L18,Config!$A$12:$B$21,2,0)) -> 0.73 | S18: =IF(N18="","",VLOOKUP(N18,Config!$D$12:$E$21,2,0)) -> 0.85 | T18: =IF(V18="Defect",IF(OR(X18="",G18="",R18=""),"",ROUND(MIN(100,VLOOKUP(X18,Config!$G$12:$H$16,2,0)*VLOOKUP(G18,Config!$I$12:$J$21,2,0)*R18),1)),IF(OR(Q18="",R18="",S18="",M18=""),"",ROUND(MIN(100,Q18*R18*S18/M18*20),1))) -> 9.9 | U18: =IF(T18="","",RANK(T18,$T$4:$T$52)) -> 13 | V18: Feature
A19: F-010 | B19: Deliver admin.* events to customer-web-app: add its ingest endpoint to the relay peer list | D19: Idea | P19: [from customer-web-app F-005 spec, 2026-07-19] cwa's cross-app identity sync (dispatch-derek/customer-web-app specs/F-005-cross-app-identity-sync.md, Prioritized there) consumes admin.user.* events as an HTTP peer of this app's F-004 relay. Producer-side precondition pinned in that spec's §3.6: this app's relay EVENT_BUS_URL peer list must include cwa's ingest endpoint (POST /api/events/ingest), with the shared ingest secret provisioned to both sides and the pinned X-Event-Delivery-Id header carried. Config-only on the relay side (comma-list peer per REQ-F004-052) plus credential provisioning/runbook. Related: D-006 (relay peer delivery lacks HMAC/mTLS + https enforcement) — adding a second peer raises that hardening's priority; cwa-side ingest auth expects the shared-secret header. Ready for /write-feature-brief. | Q19: =IF(V19="Defect","",IF(COUNT(G19:K19)<5,"",ROUND(G19*Config!$B$4+H19*Config!$B$5+I19*Config!$B$6+J19*Config!$B$7+K19*Config!$B$8,2))) | R19: =IF(L19="","",VLOOKUP(L19,Config!$A$12:$B$21,2,0)) | S19: =IF(N19="","",VLOOKUP(N19,Config!$D$12:$E$21,2,0)) | T19: =IF(V19="Defect",IF(OR(X19="",G19="",R19=""),"",ROUND(MIN(100,VLOOKUP(X19,Config!$G$12:$H$16,2,0)*VLOOKUP(G19,Config!$I$12:$J$21,2,0)*R19),1)),IF(OR(Q19="",R19="",S19="",M19=""),"",ROUND(MIN(100,Q19*R19*S19/M19*20),1))) | U19: =IF(T19="","",RANK(T19,$T$4:$T$52)) | V19: Feature
A20: F-011 | B20: Dashboard and reports for visualizing the data coming in as customer.* events from customer-web-app | D20: Idea | P20: [from customer-web-app F-007 brief, 2026-07-19] Product-owner ruling names admin-console as the near-term consumer of cwa's customer.* event stream for audit and customer-reporting purposes; this row tracks that consumer work (previously untracked — flagged as an open question in cwa's briefs/F-007-production-event-relay-twin.md). Scope sketch: consume/ingest customer.* envelopes (13 event names across 7 families in cwa's catalog: user, conversation, answer, topic, topic_user, branding, addon; 5 user events after cwa F-005) and surface dashboards/reports over them. Dependencies: cwa F-007 relay twin (Deferred in cwa's workbook until its F-005 implements) must deliver the stream; F-010 here is the mirror-image peer-list config for the opposite direction; an admin-console-side ingest receiver for customer.* does not exist yet (this app is producer-only today). Which of the 13 families the dashboards need is an open question carried in cwa's F-007 brief. Ready for /write-feature-brief. | Q20: =IF(V20="Defect","",IF(COUNT(G20:K20)<5,"",ROUND(G20*Config!$B$4+H20*Config!$B$5+I20*Config!$B$6+J20*Config!$B$7+K20*Config!$B$8,2))) | R20: =IF(L20="","",VLOOKUP(L20,Config!$A$12:$B$21,2,0)) | S20: =IF(N20="","",VLOOKUP(N20,Config!$D$12:$E$21,2,0)) | T20: =IF(V20="Defect",IF(OR(X20="",G20="",R20=""),"",ROUND(MIN(100,VLOOKUP(X20,Config!$G$12:$H$16,2,0)*VLOOKUP(G20,Config!$I$12:$J$21,2,0)*R20),1)),IF(OR(Q20="",R20="",S20="",M20=""),"",ROUND(MIN(100,Q20*R20*S20/M20*20),1))) | U20: =IF(T20="","",RANK(T20,$T$4:$T$52)) | V20: Feature
Q21: =IF(V21="Defect","",IF(COUNT(G21:K21)<5,"",ROUND(G21*Config!$B$4+H21*Config!$B$5+I21*Config!$B$6+J21*Config!$B$7+K21*Config!$B$8,2))) | R21: =IF(L21="","",VLOOKUP(L21,Config!$A$12:$B$21,2,0)) | S21: =IF(N21="","",VLOOKUP(N21,Config!$D$12:$E$21,2,0)) | T21: =IF(V21="Defect",IF(OR(X21="",G21="",R21=""),"",ROUND(MIN(100,VLOOKUP(X21,Config!$G$12:$H$16,2,0)*VLOOKUP(G21,Config!$I$12:$J$21,2,0)*R21),1)),IF(OR(Q21="",R21="",S21="",M21=""),"",ROUND(MIN(100,Q21*R21*S21/M21*20),1))) | U21: =IF(T21="","",RANK(T21,$T$4:$T$52))
